To resolve the `NullPointerException` issue correctly, it’s crucial to ensure that the `get` method on the mocked `JsonNode` always returns a valid mock object. This is necessary because the `asText()` method is called on the result of `get`. 

Here’s the revised version of the `testGetArrayValueForTags_ExceptionInAsText` method that should work without failure:

```java
@Test
public void testGetArrayValueForTags_ExceptionInAsText() {
    // Create a mock for the main JsonNode
    JsonNode jsonNode = Mockito.mock(JsonNode.class);
    
    // Create a mock for the tags JsonNode that will be returned by the get method
    JsonNode tagsNode = Mockito.mock(JsonNode.class);
    
    // Configure the main mock to return the tagsNode when get is called
    when(jsonNode.get("tags")).thenReturn(tagsNode);
    
    // Configure the tagsNode to throw an exception when asText is called
    when(tagsNode.asText()).thenThrow(new RuntimeException("Mocked exception"));

    // Call the method under test
    String[] result = alarmRepository.getArrayValueForTags(jsonNode, "tags");

    // Assert that the result is an empty array
    assertArrayEquals(new String[0], result); // Expect empty array on exception
}
```

### Explanation of the Fix:
1. **Mock Setup**: 
   - The `jsonNode` is mocked to return another mock `tagsNode` when `get("tags")` is called. This ensures that `tagsNode` is not null.
   - The `tagsNode` mock is then configured to throw a `RuntimeException` when `asText()` is called.
   
2. **Execution**: When the method `getArrayValueForTags` is executed, it will retrieve the `tagsNode`, and when `asText()` is called on that node, the exception will be thrown, triggering the catch block in the original method.

This setup ensures that the method can run without encountering a `NullPointerException`, successfully testing the exception handling logic.